Workbook
Name _Hlk169617268: Quotes!$E$575
Name _Hlk84432143: Quotes!$E$605

Sheet Quotes
A1: Quote Num. | B1: Created By | C1: Customer | D1: Cust. Contact | E1: Description | F1: Start Date | G1: Due Date | H1: Maturity Date | I1: Quote Status | J1: In L Drive | K1: Latest Rev | L1: Column1
A2: Q06 | B2: JT | C2: RSA | D2: Jon Trembley | E2: Example Quote | F2: 44837 | G2: 44837 | H2: 44837 | I2: Not Accepted | J2: No
A3: Q07 | B3: JT | C3: Avient | D3: Aaron Johnson | E3: Line C Acrison Takeover | F3: 44837 | G3: 44841 | I3: Not Accepted | J3: No
A4: Q08 | B4: TF | C4: Upstate Batavia | D4: Oleg S. | E4: Vacuum Cups | F4: 44837 | G4: 44837 | I4: PO Received | J4: Yes
A5: Q09 | B5: JRW | C5: Cedars | E5: Scara Robot Case Packing | F5: 44838 | G5: 44838 | I5: Not Accepted | J5: No
A6: Q010 | B6: TF | C6: Iberdrola | D6: Dan Arcangeli | E6: SAP Bing, Can., Geneva | F6: 44838 | G6: 44839 | I6: PO Received | J6: Yes
A7: Q011 | B7: TF | C7: Iberdrola | D7: Dan Arcangeli | E7: AMI Filmore | F7: 44839 | G7: 44841 | I7: PO Received | J7: No
A8: Q012 | B8: TF | C8: Iberdrola | D8: Dan Arcangeli | E8: AMI Mechanicville, Lockport | F8: 44839 | G8: 44841 | I8: PO Received | J8: No
A9: Q013 | B9: TF | C9: Natures Fynd | D9: Sunny | E9: MCV 3000 Service Kit | F9: 44840 | G9: 44840 | I9: PO Received | J9: Yes
A10: Q014 | B10: JT | C10: Precision Process | D10: Scott Morrow | E10: Inital Design Labor for PPI Line | F10: 44841 | G10: 44841 | H10: 44844 | I10: PO Received | J10: Yes
A11: Q015 | B11: JRW | C11: Engineered Thermal Solutions | D11: Chris Imiola | E11: Cement Cooling Water Tank & Panel Skid | F11: 44840 | G11: 44840 | I11: Not Accepted | J11: No
A12: Q016 | B12: JRW | C12: Sweetworks | D12: Guy Caccavaio | E12: Imperial Line ABB Support | F12: 44841 | G12: 44841 | I12: PO Received | J12: Yes
A13: Q017 | B13: TF | C13: Natures Fynd | D13: Sunny | E13: CPM Service Kit | F13: 44844 | I13: PO Received | J13: Yes
A14: Q018 | B14: JT | C14: Engineered Thermal Solutions | D14: Chuck Marchetta | E14: Kopple PA Cooling Water Controls | F14: 44844 | G14: 44855 | I14: Not Accepted | J14: Yes
A15: Q019 | B15: TF | C15: Lydall | D15: Mike Sanguinito | E15: Machine Guarding for Coating Line | F15: 44846 | I15: PO Received | K15: 2
A16: Q020 | B16: TF | C16: Natures Fynd | D16: Sunny | E16: Steam Trap Spares | F16: 44848 | I16: PO Received | J16: No
A17: Q021 | B17: JT | C17: Hans Kissle | D17: Nick Piccolo | E17: Level Control for Trial Pump | F17: 44848 | G17: 44848 | I17: Not Accepted | J17: Yes
A18: Q022 | B18: TF | C18: Saint- Gobain Niagra | D18: Jeffe Villont | E18: Gel Extruder Abrasive Line | F18: 44854 | I18: Not Accepted | J18: Yes
A19: Q023 | B19: JRW | C19: Saint Gobain Albion | D19: Ron Paeth | E19: FibaTape Packing Line Automation | F19: 44855 | G19: 44855 | I19: Not Accepted | J19: No
A20: Q024 | B20: JRW | C20: Saint Gobain Albion | D20: Ron Paeth | E20: V38 Mixing Line Ingredient Depalletizing Automation | F20: 44858 | G20: 44858 | I20: Not Accepted | J20: No
A21: Q025 | B21: TF | C21: Curaleaf | D21: Luke Burwell | E21: CIP System | F21: 44865 | I21: Not Accepted | J21: Yes
A22: Q026 | B22: JT | C22: Saint Gobain NF | D22: Sean Gokey, Wyatt Wolf | E22: Spray Dryer #2 Recontrol | F22: 44865 | G22: 44866 | I22: Not Accepted | J22: No
A23: Q027 | B23: JRW | C23: Saint Gobain Albion | D23: Ron Paeth | E23: Spackle Line Printing Solution | F23: 44866 | G23: 44866 | I23: Not Accepted | J23: Yes
A24: Q028 | B24: TF | C24: Thrive Foods | D24: Jacob Demaray | E24: Tray Washer Modification | F24: 44867 | I24: PO Received | J24: Yes
A25: Q029 | B25: TF | C25: Thrive Foods | D25: Jacob Demaray | E25: Tray Cart | F25: 44867 | I25: Not Accepted | J25: Yes
A26: Q030 | B26: TF | C26: Chem Aqua | D26: Nick Valente | E26: Nebraska Ozone | F26: 44872 | G26: 44873 | I26: PO Received | J26: Yes
A27: Q031 | B27: JT | C27: Aries | D27: Dan Doyle | E27: Seal Water Overflow Switch | F27: 44872 | G27: 44872 | I27: Not Accepted | J27: Yes
A28: Q032 | B28: TF | C28: Iberdrola | D28: Dan Arcangeli | E28: Bulkheads | F28: 44873 | I28: PO Received | J28: Yes
A29: Q033 | B29: JT | C29: Saint Gobain CertainTeed | D29: John Marciniak | E29: 20:1 Gearbox Difference - In Job 3501 Quote Folder | F29: 44874 | G29: 44874 | I29: PO Received | J29: Yes
A30: Q034 | B30: TF | C30: Chem Aqua | D30: Nick Valente | E30: Spare Parts for Ozone | F30: 44874 | I30: Not Accepted | J30: Yes
A31: Q035 | B31: JT | C31: Engineered Thermal Solutions | D31: Chuck Marchetta | E31: Liberty Tubulars Tower Control Panel | F31: 44883 | G31: 44883 | I31: PO Received | J31: Yes
A32: Q036 | B32: JT | C32: Hans Kissle | D32: Nick Piccolo | E32: MCC and Switch Gear Alternatives | F32: 44887 | I32: Not Accepted | J32: Yes
A33: Q037 | B33: JT | C33: Precision Process | D33: Scott Morrow | E33: T&M Not to exceed update - In Job 3594 Folder | F33: 44894 | G33: 44894 | I33: PO Received | J33: Yes
A34: Q038 | B34: TF | C34: Fresenius Kabi | D34: Andrey Svintozelsky | E34: CIP Flowmeter Replacement | F34: 44897 | I34: PO Received | J34: Yes
A35: Q039 | B35: TF | C35: Avangrid | D35: Dan Arcangeli | E35: SAP Hornell Liberty | F35: 44897 | I35: PO Received | J35: Yes
A36: Q040 | B36: TF | C36: Fresenius Kabi | D36: Andrey Svintozelsky | E36: WIFI Antenna Modification | F36: 44900 | I36: PO Received | J36: Yes
A37: Q041 | B37: TF | C37: Natures Fynd | D37: Vrushank Patel | E37: Filler Drain Leg | F37: 44901 | I37: PO Received | J37: Yes | K37: Rev1
A38: Q042 | B38: JW | C38: McAlpin | D38: John Wilcox | E38: Robot 23 PLC Programming Changes | F38: 44904 | I38: Not Accepted | J38: No
A39: Q043 | B39: JT | C39: Saint Gobain CertainTeed | D39: John Marciniak | E39: Saw Panel Drive Upgrade to Allen Bradley | F39: 44909 | I39: Not Accepted | J39: Yes
A40: Q044 | B40: JT | C40: Engineered Thermal Solutions | D40: Chuck Marchetta | E40: Pump Skid for Cooling Water | F40: 44911 | G40: 44915 | I40: Not Accepted | J40: No
...

Sheet Tasks
B2: Customer | C2: Job | D2: Meeting Code | E2: Assigned To | F2: Priority | G2: Deadline | H2: Task | I2: Status | J2: Cust. Contact | K2: Maturity Timeline | L2: Status Notes
B3: Phinney | C3: 3423 - TS-121 Die Press | D3: PAN, AD | E3: Jon | F3: 1 | G3: 44775 | H3: Billing Status | I3: Archive | L3: Edits reviewed and sent to Christina - invoice pending
B4: Billitier | C4: P0833 - UR Pharm Door PLC | D4: CD, AD | E4: Jon | F4: 1 | G4: 44781 | H4: Billing | I4: Archive | L4: Reached out to Dan Bamann on 8/23 for status
B5: 4015 | C5: R & D | D5: PAN | E5: Brandon, Nick | F5: 1 | G5: 44813 | H5: Perform some market research on what UPS units are on the market that support Lithium-ion battery tech | I5: Done | L5: Have a meeting scheduled with Avangrid on 9/12 to prepare for. No 480V UPS on the market
B6: Aries | C6: 120V Distribution in each MCC | D6: QT | E6: Jon | F6: 2 | G6: 44796 | H6: Quote | I6: Archive
B7: CertainTeed | C7: Macron Gearbox Issue | D7: AD | E7: Jon, Tom | F7: 1 | G7: 44774 | H7: Finish this job NOW! | I7: Done | L7: CO PO came in wrong. Need John M to fix
B8: Precision Process | C8: 3519A - Change Order | D8: AD | E8: Jon | F8: 1 | G8: 44788 | H8: Ensure we do or do not need to bill this | I8: Archive | L8: Don't need to bill
B9: Cedars | C9: 3562 - NF Expansion | D9: PAN | E9: Jon | F9: 1 | G9: 44797 | H9: Order Parts - 6 Prox junction box with cables; 8 Prox Juntion Box with cables; 16 prox Junction Box with cables | I9: Archive
B10: Aries | C10: P0XXX | D10: IT | E10: Jon | F10: 1 | G10: 44812 | H10: Follow up with Aries IT and perform request | I10: Done
B11: Buffalo Games | C11: 3493 - Press 6 Controls System | D11: PAN, AD | E11: Jon | G11: 44768 | H11: Change Order | I11: Archive
B12: McAlpin | C12: CC12 (3508 Robot Duplication) | D12: QT | E12: Brandon | F12: 2 | G12: 44809 | H12: Get an updated cell price from Jim mail and reply to McAlpin's RFQ | I12: Archive | L12: Meeting with customer 9/12 - request for ballpark pricing
B13: Buffalo Games | C13: 3493 - Press 6 Controls System | D13: PAN, AD | E13: Jon | G13: 44769 | H13: Billing Status | I13: Archive
B14: Caldwell | C14: 3494 | D14: PAN, AD | E14: Brandon | G14: 44781 | H14: Billing Status | I14: Archive | L14: Billed
B15: Sweetworks | C15: Delver Depositor Service | D15: AD | E15: Jon | F15: 1 | G15: 44790 | H15: Write service report and bill | I15: Archive | L15: RSA to no-quote depositor.
B16: Campbell | C16: Milwalkee | D16: PAN | E16: Brandon | F16: 1 | G16: 44788 | H16: Transfer PDF to Excel BOM | I16: Archive
B17: Cedars | C17: 3444 - CIP Skid | D17: PAN | E17: Nick | F17: 1 | G17: 44788 | H17: Edit Drawing, add terms for door harness | I17: Archive
B18: Cedars | C18: 3479 - Barcode Scanner | D18: AD | E18: Ricky, Jon | F18: 1 | G18: 44789 | H18: Billing | I18: Done | L18: Pending review with Rick
B19: Aries/Riggs | C19: Billing | D19: AD | E19: Jon | F19: 1 | G19: 44817 | H19: Get us paid | I19: Done | L19: Renus claims payment by end of month
B20: Aries | C20: September Remote Support | D20: QT | E20: Jon | F20: 2 | G20: 44799 | H20: Possible RFQ to support Aries Linden through September Gasifier Run | I20: Done | L20: Get details on date range
B21: Aries | C21: P0XXX | D21: AD | E21: Jon | F21: 2 | G21: 44813 | H21: Write service report for Tri-mer HMI System | I21: Archive | J21: Dan Doyle | L21: Never Done
B22: TakeForm | C22: Dust Collection and VAC Pump Panel | D22: QT | E22: Jon | F22: 1 | G22: 44789 | H22: Quote Panel | I22: Archive
B23: Avangrid | C23: 002I-C Quote Request | D23: QT | E23: Tom, Jon | F23: 1 | G23: 44806 | H23: Send response to avangrid on RFQ for 002I-C | I23: Done | J23: David Stowell
B24: Avangrid | C24: AMI - 3 more locations | D24: QT | E24: Tom | F24: 2 | G24: 44841 | H24: 3 more locations quote | I24: Done
B25: Aries | C25: Review all Billing | D25: AD | E25: Jon | F25: 1 | G25: 44791 | H25: Review all Billing | I25: Archive | L25: Waiting for Christina to review list from James Nesbitt; List has been reviewed once, waiting to review one last report from Brandon
B26: Cedars | C26: 3444 - CIP Skid | D26: ME | E26: Mike | F26: 2 | G26: 44769 | H26: Mechanical Finalization | I26: Archive | L26: Pending update from Ricky
B27: Avangrid | C27: Next two locations | D27: QT | E27: Tom | F27: 1 | G27: 44823 | H27: Did we get a response by 9/19? | I27: Done | L27: Need to review with Rick
B28: Avangrid | C28: Bulk heads | D28: QT | E28: Tom | F28: 4 | G28: 44876 | H28: Follow Up | I28: Done | L28: RFQ out to vendor - will flip when recieved
B29: Iberdrola | C29: 3523 - 100 Cabinet Build | D29: PAN | E29: Nick | F29: 1 | G29: 44788 | H29: Are we supplying Kits? IB102 | I29: Archive | L29: If yes, put together BOM
B30: Avangrid | C30: SAP Bing Can Geneva | D30: QT | E30: Tom | F30: 2 | G30: 44844 | H30: Follow up | I30: Done
B31: ETS | C31: 3567 - Argentina | D31: PAN | E31: Jon | F31: 1 | G31: 44813 | H31: Change Order | I31: Done | L31: Include changes in engineering in change order
B32: Cedars | C32: 3562 - NF Line (3 panels) | D32: PAN | E32: Nick | F32: 1 | G32: 44789 | H32: Verify Stock List | I32: Archive
B33: Iberdrola | C33: 3470 - 30" Cabinet Re-Work | D33: PAN | E33: Nick | F33: 1 | G33: 44795 | H33: In progress, Pete might want these instead of two new cabinets | I33: Archive | L33: New P.O. 3470A, finishing two 30" cabinets for Pete
B34: Baskin Live Stock | C34: QT Follow-up | D34: CD, QT | E34: Jon | F34: 2 | G34: 44788 | H34: QT Follow-up | I34: Archive
B35: Cedars | C35: 3547 - Bag Filler | D35: PAN, AD | E35: Nick | F35: 2 | G35: 44792 | H35: Verify Stock List Status | I35: Archive
B36: Natures Fynd | C36: 3569 - Chiller Cart | D36: AD | E36: Jon | F36: 1 | G36: 44797 | H36: Bill | I36: Done | L36: Checked Numbers 11/9/22 - Christina is clreaed to send Bill to Zach
B37: Cedars | C37: 3554 - GEA Homogenizer Controls | D37: PAN | E37: Nick | F37: 2 | G37: 44792 | H37: Finish Electrical Integration with Homogenizer | I37: Archive | L37: Putting D9P HMI in door
B38: Cedars | C38: 3444 - CIP Skid | D38: PAN | E38: PB | F38: 1 | G38: 44790 | H38: Electrical Finalization | I38: Archive | L38: More changes to electrical design need to be made...again
B39: Cedars | C39: 3554 - Homog 2 | D39: PAN | E39: Nick | F39: 2 | G39: 44792 | H39: Reorder any Canceled Components | I39: Archive | L39: We're not doing this job
B40: Cedars | C40: 3554 - Homog 2 | D40: ME, PAN, AD | E40: Notes | F40: 3 | G40: 44785 | H40: Homog 2 | I40: Archive | L40: We're not doing this job
B41: Cedars | C41: 3444 - CIP Skid | D41: AD | E41: Brandon | F41: 1 | G41: 44802 | H41: Documentation - Consoledate under Cedars | I41: Archive | L41: Network Drawings
...

Sheet Projects
A1: Project Number | B1: Associated Jobs | C1: Created By | D1: Customer | E1: Cust. Contact | F1: Description | G1: Start Date | H1: Due Date | I1: Job Status | J1: In QB | K1: In L Drive | L1: Quote Num | M1: Invoiced | N1: Invoice Date | O1: Notes
A2: 359 | B2: P0961 | C2: JT | D2: Precision Process | E2: Scott Morrow | F2: Inital Engineering for Plating Line | G2: 44838 | I2: Billed | J2: Yes | K2: Yes | L2: Q0009 | M2: 1 | N2: 44841
A3: 2125 | C3: RS | D3: RSA | F3: Apollo Work | G3: ? | J3: Yes
A4: 3289 | C4: RS | D4: HydroGrow | F4: HydroGrow - Header Only | G4: 44456 | J4: Yes
A5: 3352 | C5: TF | D5: RSA | F5: Ozone R&D Work | G5: 44013 | J5: Yes
A6: 3374 | C6: CF | D6: RSA | F6: RSA Continuous Improvement | G6: N/A | J6: Yes
A7: 3398 | C7: RS | D7: RSA | F7: New Building | G7: 44272 | J7: Yes
A8: 3400 | C8: MM | D8: Oatka | F8: SABR Line 1 Slide Doors | G8: 44277 | J8: Yes
A9: 3401 | C9: RS | D9: Poverty Hill | F9: 8" Piping on Sludge Fit | G9: 44277 | J9: Yes
A10: 3402 | C10: SD | D10: Saint Gobain Albion | F10: Machine Return Line Valves | G10: 44284 | I10: Closed | J10: Yes | K10: Yes
A11: 3403 | C11: TF/MM | D11: Oatka | F11: A+R Sweeper Arm Rebuild | G11: 44285 | J11: Yes
A12: 3404 | C12: TF | D12: AEI/Trek | F12: Prototype Burn In Enclosure | G12: 44288 | J12: Yes
A13: 3405 | C13: JT | D13: Mizkan | F13: Wrapper HMI Duplication | G13: 44288 | J13: Yes
A14: 3406 | C14: MM | G14: 44292 | J14: No
A15: 3407 | C15: TF | D15: Oatka | F15: Can Filler Door | G15: 44300 | J15: Yes | L15: Q0TD0312-1
A16: 3408 | C16: TF | D16: Campbell | F16: Flow Panel | G16: 44302 | J16: Yes | L16: QCMP040121
A17: 3409 | C17: RS | D17: Oatka | F17: Filter Screens Gooding Tower | G17: 44302 | J17: Yes | L17: QOTD041621-1
A18: 3410 | C18: RS | D18: Mizkan | F18: Railing | G18: 44306 | J18: Yes
A19: 3411 | C19: JT | D19: Concord | F19: Software Support | G19: 44307 | J19: Yes
A20: 3412 | C20: JW | D20: Novolex | F20: Unloader Bagging Station | G20: 44316 | I20: Closed | J20: No
A21: 3413 | C21: JT | D21: Aries | F21: Panels - Main, Radio and Drive - DeWatering Project | G21: 44322 | J21: Yes
A22: 3414 | D22: Chem Aqua | F22: 4 - Mott's Ozone Units | G22: 44328 | J22: Yes
A23: 3415 | C23: BB | D23: ETS | F23: BOM Creator | G23: 44335 | J23: Yes
A24: 3416 | C24: JT | D24: Moley Magnetics | F24: Batching System Software Dev | G24: 44398 | J24: No
A25: 3417 | C25: JT | D25: Concord | F25: PLC 5 Upgrade CS3 | G25: 44337 | J25: Yes
A26: 3418 | C26: RS | D26: Campbell | F26: Tote Batching Skid | G26: 44337 | J26: No
A27: 3419 | C27: MP | D27: Oatka | F27: CIP Panel | G27: 44341 | J27: Yes | L27: QOTD032621
A28: 3420 | C28: MP | D28: Cardinal | F28: Hydrolic Tank Repair | G28: 44342 | J28: Yes
A29: 3421 | C29: MP/MM | D29: Saint Gobain Albion | F29: Tanks/Racks | G29: 44342 | I29: Closed | J29: No
A30: 3422 | C30: GF | D30: Mizkan | F30: Evaluation of Containment Phasel | G30: 44357 | J30: Yes
A31: 3423 | D31: Phinney | F31: Die Press Control Panel | G31: 44361 | J31: No | K31: Yes | L31: PO#11247
A32: 3424 | C32: TJF | D32: ETS | F32: Control Panel w/VFD | G32: 44369 | J32: No | L32: QETS022621-1
A33: 3425 | C33: TJF | D33: Nature's Fynd Yodelay | F33: Yodelay Filler Hood | G33: 44371 | J33: No | L33: QNFD062321
A34: 3426 | C34: Ed/CF | D34: Concord | F34: Homogenizer Repair | G34: 44371 | J34: Yes
A35: 3427 | C35: MP | D35: Brightmark | F35: Piping Quote | G35: 44372 | J35: Yes
A36: 3428 | C36: MM | D36: Oatka | F36: Gaurd Doors | G36: 44376 | J36: Yes
A37: 3429 | C37: TF | D37: AEI/Trek | F37: PCS Bench Enclosure | G37: 44383 | J37: No
A38: 3430 | C38: SD | D38: Oatka | F38: Rosemont Lvl Switch + Engineering | G38: 44384 | I38: Closed | J38: No | K38: Yes
A39: 3431 | C39: MM | D39: Mizkan | F39: Lyndonville Bottling Tanks P&ID | G39: 44391 | J39: No
A40: 3432 | C40: TJF | D40: Mizkan | F40: Cleaning Knife & Gaurding | G40: 44393 | J40: No | L40: QM2K071621
...

Sheet Parts and Services
A1: Job Number | B1: Created By | C1: Customer | D1: Cust. Contact | E1: Description | F1: Vendor | G1: Start Date | H1: Due Date | I1: Job Status | J1: In QB | K1: In L Drive | L1: Quote Num | M1: Invoiced | N1: Date Inv | O1: Notes
A2: P0738 | B2: RDS | C2: Cedar's | E2: Twin Scre Pump and Seals | G2: 44585
A3: P0773 | B3: SD | C3: Cedar's | E3: Cream cheese pump RMA | G3: 44627 | I3: Billed | J3: Yes | M3: 100 | N3: 44887
A4: P0800 | B4: SD | C4: Cedar's | E4: Baldor Motor | G4: 44657 | I4: Billed
A5: P0801 | B5: SD | C5: Campbell | E5: VFDs | G5: 44658 | I5: Billed | J5: Yes | L5: CN10256369 | M5: 100 | N5: 44852
A6: P0802 | B6: SD | C6: Big Ditch | E6: Coriolis Meter | G6: 44658 | I6: Billed | L6: 2022-04-07-MBK-01
A7: P0803 | B7: RSJ | C7: Nature's Fynd | E7: Single Homogenizer Trail | G7: 44659 | J7: Yes | M7: 100 | N7: 44873
A8: P0804 | B8: SD | C8: CSC Sugar | E8: Spare Parts | G8: 44662 | I8: Billed
A9: P0805 | B9: SD | C9: Northeast Industrial | E9: Photosensor | G9: 44663 | I9: Billed | L9: 204574
A10: P0806 | B10: TF | C10: Upstate Batavia | E10: Vacuum Ejector | G10: 44664 | M10: 100 | N10: 44771
A11: P0807 | B11: SD | C11: Northeast Industrial | E11: Photosensors and Relays | G11: 44664 | I11: Billed | L11: 204629
A12: P0808 | B12: SD | C12: Heartfelt | E12: Steam Generator | G12: 44693 | I12: Billed | L12: N/A
A13: P0809 | B13: MP/TF | C13: Certainteed | E13: Jaw Gripper | G13: 44665 | L13: 3002128449
A14: P0810 | B14: MP | C14: Cedar's | E14: RTD and Wiring Puck | G14: 44666 | L14: 1-193200
A15: P0811 | B15: SD | C15: Campbell | E15: Proxes and Brackets | G15: 44669 | I15: Billed | L15: 4505446099
A16: P0812 | B16: SD | C16: Northeast Industrial | E16: Push Buttons | G16: 44670 | I16: Billed | L16: 204788
A17: P0813 | B17: KR | C17: Midland Asphalt | E17: Bray 920930 w Mounting Units | G17: 44670
A18: P0814 | B18: SD | C18: LiDestri | E18: Valves | G18: 44672 | I18: Billed | L18: 332519
A19: P0815 | B19: SD | C19: Oatka | E19: Parts | G19: 44672 | I19: Billed | L19: P0202276
A20: P0816 | B20: SD | C20: LiDestri | E20: Valves | G20: 44672 | I20: Billed | L20: 332534
A21: P0817 | B21: SD | C21: EJ Gallo | E21: ILM RMA | G21: 44678 | I21: Billed | J21: Yes | M21: 100 | N21: 44925
A22: P0818 | B22: SD | C22: Upstate Batavia | E22: Turk Prox Plugs | G22: 44678 | I22: Billed | L22: 27001C016-0000-000
A23: P0819 | B23: SD | C23: Upstate w/ Seneca | E23: Manifold Parts | G23: 44680 | I23: Billed
A24: P0820 | B24: KR | C24: Midland Asphalt | E24: Grease Gun | G24: 44683
A25: P0821 | B25: RSJ | C25: Nature's Fynd | G25: 44683 | I25: Billed | J25: Yes | M25: 100 | N25: 44873
A26: P0822 | B26: SD | C26: CSC Sugar | E26: Seal Kits | G26: 44685 | I26: Billed | L26: 54-2653
A27: P0823 | B27: SD | C27: CSC Sugar | E27: Seal Kits 2 | G27: 44685 | I27: Billed | L27: 54-2660
A28: P0824 | B28: SD | C28: Upstate Batavia | E28: Pneumatic Cylinder | G28: 44686 | I28: Billed | L28: 2700K027-0000-000
A29: P0825 | B29: SD | C29: Northeast Industrial | E29: Sensagaurd | G29: 44687 | I29: Billed | L29: 205541
A30: P0826 | B30: SD | C30: Campbell | E30: Gantes and Elbows | G30: 44687 | I30: Billed | L30: 4505467239
A31: P0827 | B31: MP/RSJ/JT | C31: Certainteed | E31: 1762-OF4 | G31: 44691
A32: P0828 | B32: SD | C32: Northeast Industrial | E32: PWRFLX Drives / HP | G32: 44692 | I32: Billed | J32: Yes | L32: 205751 | M32: 100 | N32: 44907 | O32: 3 drives remain partial billing 5,9,11
A33: P0829 | B33: SD | C33: Concord | E33: Gear Drive | G33: 44692 | I33: Billed | L33: CP2201
A34: P0830 | B34: SD | C34: Richards Equipment | E34: Seal Kit | G34: 44693 | I34: Billed | L34: 20222489
A35: P0831 | B35: JT | C35: Qualitrol | E35: Onsite Service | G35: 44693 | J35: Yes | L35: Onsite Controls | M35: 1 | N35: 44875
A36: P0832 | B36: SD | C36: Heartfelt | E36: Steam Generation | G36: 44693 | I36: Billed
A37: P0833 | B37: JT | C37: Billitier Electrical | E37: ??? Onsite | G37: 44693
A38: P0834 | B38: MM | C38: Heveron Electric | E38: Dryer Plate | G38: 44693
A39: P0835 | B39: SD | C39: Cedar's | E39: Pressure Trans + RTDs | G39: 44697 | I39: Billed | L39: 1-193964
A40: P0836 | B40: SD | C40: LiDestri | E40: Angle Seat Valves | G40: 44697 | I40: Billed | L40: 333766
...

Sheet Checks and Stats
B1: Team Allocation: | D1: =SUM(D4:D1048576)/SUM($C$4:$C$1048576) -> #DIV/0! | F1: =SUM(F4:F1048576)/SUM($C$4:$C$1048576) -> #DIV/0! | H1: =SUM(H4:H1048576)/SUM($C$4:$C$1048576) -> #DIV/0! | J1: =SUM(J4:J1048576)/SUM($C$4:$C$1048576) -> #DIV/0! | S1: Task Completion
C2: Goal: | D2: 0.2 | F2: 0.6 | H2: 0.2 | S2: Open | T2: =COUNTIF(Table1[Status],'Checks and Stats'!S2)/(COUNTA(Table1[Status])-COUNTIF(Table1[Status],"Archive")) -> 0
B3: Assigned To | C3: Num Tasks | D3: Critical | F3: High | H3: Medium | J3: Low | L3: Assigned To | M3: Critical | N3: High | O3: Medium | P3: Low | S3: Done | T3: =COUNTIF(Table1[Status],'Checks and Stats'!S3)/(COUNTA(Table1[Status])-COUNTIF(Table1[Status],"Archive")) -> 1
B4: {=_xlfn.UNIQUE(_xlfn.TEXTSPLIT(_xlfn.UNIQUE(Table1[Assigned To]),","))} -> Jon | C4: =COUNTIF(Table1[Assigned To],"*" & $B4) + COUNTIF(Table1[Assigned To],$B4 & ",*") - COUNTIFS(Table1[Assigned To],"*" & $B4,Table1[Status],"Archive") - COUNTIFS(Table1[Assigned To],$B4 & ",*",Table1[Status],"Archive") - COUNTIFS(Table1[Assigned To],"*" & $B4,Table1[Status],"Done") - COUNTIFS(Table1[Assigned To],$B4 & ",*",Table1[Status],"Done") -> 0 | D4: =COUNTIFS(Table1[Assigned To],"*" & $B4,Table1[Priority],"1") + COUNTIFS(Table1[Assigned To],$B4 & ",*",Table1[Priority],"1") - COUNTIFS(Table1[Assigned To],"*" & $B4,Table1[Status],"Archive",Table1[Priority],"1") - COUNTIFS(Table1[Assigned To],$B4 & ",*",Table1[Status],"Archive",Table1[Priority],"1") - COUNTIFS(Table1[Assigned To],"*" & $B4,Table1[Status],"Done",Table1[Priority],"1") - COUNTIFS(Table1[Assigned To],$B4 & ",*",Table1[Status],"Done",Table1[Priority],"1") -> 0 | E4: =D4/C4 -> #DIV/0! | F4: =COUNTIFS(Table1[Assigned To],"*" & $B4,Table1[Priority],"2") + COUNTIFS(Table1[Assigned To],$B4 & ",*",Table1[Priority],"2") - COUNTIFS(Table1[Assigned To],"*" & $B4,Table1[Status],"Archive",Table1[Priority],"2") - COUNTIFS(Table1[Assigned To],$B4 & ",*",Table1[Status],"Archive",Table1[Priority],"2") - COUNTIFS(Table1[Assigned To],"*" & $B4,Table1[Status],"Done",Table1[Priority],"2") - COUNTIFS(Table1[Assigned To],$B4 & ",*",Table1[Status],"Done",Table1[Priority],"2") -> 0 | G4: =F4/C4 -> #DIV/0! | H4: =COUNTIFS(Table1[Assigned To],"*" & $B4,Table1[Priority],"3") + COUNTIFS(Table1[Assigned To],$B4 & ",*",Table1[Priority],"3") - COUNTIFS(Table1[Assigned To],"*" & $B4,Table1[Status],"Archive",Table1[Priority],"3") - COUNTIFS(Table1[Assigned To],$B4 & ",*",Table1[Status],"Archive",Table1[Priority],"3") - COUNTIFS(Table1[Assigned To],"*" & $B4,Table1[Status],"Done",Table1[Priority],"3") - COUNTIFS(Table1[Assigned To],$B4 & ",*",Table1[Status],"Done",Table1[Priority],"3") -> 0 | I4: =H4/C4 -> #DIV/0! | J4: =COUNTIFS(Table1[Assigned To],"*" & $B4,Table1[Priority],"4") + COUNTIFS(Table1[Assigned To],$B4 & ",*",Table1[Priority],"4") - COUNTIFS(Table1[Assigned To],"*" & $B4,Table1[Status],"Archive",Table1[Priority],"4") - COUNTIFS(Table1[Assigned To],$B4 & ",*",Table1[Status],"Archive",Table1[Priority],"4") - COUNTIFS(Table1[Assigned To],"*" & $B4,Table1[Status],"Done",Table1[Priority],"4") - COUNTIFS(Table1[Assigned To],$B4 & ",*",Table1[Status],"Done",Table1[Priority],"4") -> 0 | K4: =J4/C4 -> #DIV/0! | L4: {=_xlfn.UNIQUE(_xlfn._xlws.FILTER(Table1[Assigned To],Table1[Assigned To]<>""))} -> Jon | M4: =IF(AND((D4/$C4)>D$2+0.05,$C4>4),2,IF(AND((D4/$C4)>D$2,$C4>4),1,0)) -> #DIV/0! | N4: =IF(AND((F4/$C4)>F$2+0.05,$C4>4),2,IF(AND((F4/$C4)>F$2,$C4>4),1,0)) -> #DIV/0! | O4: =IF(AND((H4/$C4)>H$2+0.05,$C4>4),2,IF(AND((H4/$C4)>H$2,$C4>4),1,0)) -> #DIV/0! | P4: =IF(AND((J4/$C4)>J$2,$C4>4),1,0) -> #DIV/0! | Q4: =SUM(D4,F4,H4,J4) -> 0 | S4: External Dependency | T4: =COUNTIF(Table1[Status],'Checks and Stats'!S4)/(COUNTA(Table1[Status])-COUNTIF(Table1[Status],"Archive")) -> 0
B5: Brandon | C5: =COUNTIF(Table1[Assigned To],"*" & $B5) + COUNTIF(Table1[Assigned To],$B5 & ",*") - COUNTIFS(Table1[Assigned To],"*" & $B5,Table1[Status],"Archive") - COUNTIFS(Table1[Assigned To],$B5 & ",*",Table1[Status],"Archive") - COUNTIFS(Table1[Assigned To],"*" & $B5,Table1[Status],"Done") - COUNTIFS(Table1[Assigned To],$B5 & ",*",Table1[Status],"Done") -> 0 | D5: =COUNTIFS(Table1[Assigned To],"*" & $B5,Table1[Priority],"1") + COUNTIFS(Table1[Assigned To],$B5 & ",*",Table1[Priority],"1") - COUNTIFS(Table1[Assigned To],"*" & $B5,Table1[Status],"Archive",Table1[Priority],"1") - COUNTIFS(Table1[Assigned To],$B5 & ",*",Table1[Status],"Archive",Table1[Priority],"1") - COUNTIFS(Table1[Assigned To],"*" & $B5,Table1[Status],"Done",Table1[Priority],"1") - COUNTIFS(Table1[Assigned To],$B5 & ",*",Table1[Status],"Done",Table1[Priority],"1") -> 0 | E5: =IF(C5=0,0,D5/C5) -> 0 | F5: =COUNTIFS(Table1[Assigned To],"*" & $B5,Table1[Priority],"2") + COUNTIFS(Table1[Assigned To],$B5 & ",*",Table1[Priority],"2") - COUNTIFS(Table1[Assigned To],"*" & $B5,Table1[Status],"Archive",Table1[Priority],"2") - COUNTIFS(Table1[Assigned To],$B5 & ",*",Table1[Status],"Archive",Table1[Priority],"2") - COUNTIFS(Table1[Assigned To],"*" & $B5,Table1[Status],"Done",Table1[Priority],"2") - COUNTIFS(Table1[Assigned To],$B5 & ",*",Table1[Status],"Done",Table1[Priority],"2") -> 0 | G5: =IF(C5=0,0,F5/C5) -> 0 | H5: =COUNTIFS(Table1[Assigned To],"*" & $B5,Table1[Priority],"3") + COUNTIFS(Table1[Assigned To],$B5 & ",*",Table1[Priority],"3") - COUNTIFS(Table1[Assigned To],"*" & $B5,Table1[Status],"Archive",Table1[Priority],"3") - COUNTIFS(Table1[Assigned To],$B5 & ",*",Table1[Status],"Archive",Table1[Priority],"3") - COUNTIFS(Table1[Assigned To],"*" & $B5,Table1[Status],"Done",Table1[Priority],"3") - COUNTIFS(Table1[Assigned To],$B5 & ",*",Table1[Status],"Done",Table1[Priority],"3") -> 0 | I5: =IF(C5=0,0,H5/C5) -> 0 | J5: =COUNTIFS(Table1[Assigned To],"*" & $B5,Table1[Priority],"4") + COUNTIFS(Table1[Assigned To],$B5 & ",*",Table1[Priority],"4") - COUNTIFS(Table1[Assigned To],"*" & $B5,Table1[Status],"Archive",Table1[Priority],"4") - COUNTIFS(Table1[Assigned To],$B5 & ",*",Table1[Status],"Archive",Table1[Priority],"4") - COUNTIFS(Table1[Assigned To],"*" & $B5,Table1[Status],"Done",Table1[Priority],"4") - COUNTIFS(Table1[Assigned To],$B5 & ",*",Table1[Status],"Done",Table1[Priority],"4") -> 0 | K5: =IF(C5=0,0,J5/C5) -> 0 | L5: Brandon, Nick | M5: =IF(AND((D5/$C5)>D$2+0.05,$C5>4),2,IF(AND((D5/$C5)>D$2,$C5>4),1,0)) -> #DIV/0! | N5: =IF(AND((F5/$C5)>F$2+0.05,$C5>4),2,IF(AND((F5/$C5)>F$2,$C5>4),1,0)) -> #DIV/0! | O5: =IF(AND((H5/$C5)>H$2+0.05,$C5>4),2,IF(AND((H5/$C5)>H$2,$C5>4),1,0)) -> #DIV/0! | P5: =IF(AND((J5/$C5)>J$2,$C5>4),1,0) -> #DIV/0! | Q5: =SUM(D5,F5,H5,J5) -> 0 | S5: Internal Dependency | T5: =COUNTIF(Table1[Status],'Checks and Stats'!S5)/(COUNTA(Table1[Status])-COUNTIF(Table1[Status],"Archive")) -> 0
B6: Nick | C6: =COUNTIF(Table1[Assigned To],"*" & $B6) + COUNTIF(Table1[Assigned To],$B6 & ",*") - COUNTIFS(Table1[Assigned To],"*" & $B6,Table1[Status],"Archive") - COUNTIFS(Table1[Assigned To],$B6 & ",*",Table1[Status],"Archive") - COUNTIFS(Table1[Assigned To],"*" & $B6,Table1[Status],"Done") - COUNTIFS(Table1[Assigned To],$B6 & ",*",Table1[Status],"Done") -> 0 | D6: =COUNTIFS(Table1[Assigned To],"*" & $B6,Table1[Priority],"1") + COUNTIFS(Table1[Assigned To],$B6 & ",*",Table1[Priority],"1") - COUNTIFS(Table1[Assigned To],"*" & $B6,Table1[Status],"Archive",Table1[Priority],"1") - COUNTIFS(Table1[Assigned To],$B6 & ",*",Table1[Status],"Archive",Table1[Priority],"1") - COUNTIFS(Table1[Assigned To],"*" & $B6,Table1[Status],"Done",Table1[Priority],"1") - COUNTIFS(Table1[Assigned To],$B6 & ",*",Table1[Status],"Done",Table1[Priority],"1") -> 0 | E6: =IF(C6=0,0,D6/C6) -> 0 | F6: =COUNTIFS(Table1[Assigned To],"*" & $B6,Table1[Priority],"2") + COUNTIFS(Table1[Assigned To],$B6 & ",*",Table1[Priority],"2") - COUNTIFS(Table1[Assigned To],"*" & $B6,Table1[Status],"Archive",Table1[Priority],"2") - COUNTIFS(Table1[Assigned To],$B6 & ",*",Table1[Status],"Archive",Table1[Priority],"2") - COUNTIFS(Table1[Assigned To],"*" & $B6,Table1[Status],"Done",Table1[Priority],"2") - COUNTIFS(Table1[Assigned To],$B6 & ",*",Table1[Status],"Done",Table1[Priority],"2") -> 0 | G6: =IF(C6=0,0,F6/C6) -> 0 | H6: =COUNTIFS(Table1[Assigned To],"*" & $B6,Table1[Priority],"3") + COUNTIFS(Table1[Assigned To],$B6 & ",*",Table1[Priority],"3") - COUNTIFS(Table1[Assigned To],"*" & $B6,Table1[Status],"Archive",Table1[Priority],"3") - COUNTIFS(Table1[Assigned To],$B6 & ",*",Table1[Status],"Archive",Table1[Priority],"3") - COUNTIFS(Table1[Assigned To],"*" & $B6,Table1[Status],"Done",Table1[Priority],"3") - COUNTIFS(Table1[Assigned To],$B6 & ",*",Table1[Status],"Done",Table1[Priority],"3") -> 0 | I6: =IF(C6=0,0,H6/C6) -> 0 | J6: =COUNTIFS(Table1[Assigned To],"*" & $B6,Table1[Priority],"4") + COUNTIFS(Table1[Assigned To],$B6 & ",*",Table1[Priority],"4") - COUNTIFS(Table1[Assigned To],"*" & $B6,Table1[Status],"Archive",Table1[Priority],"4") - COUNTIFS(Table1[Assigned To],$B6 & ",*",Table1[Status],"Archive",Table1[Priority],"4") - COUNTIFS(Table1[Assigned To],"*" & $B6,Table1[Status],"Done",Table1[Priority],"4") - COUNTIFS(Table1[Assigned To],$B6 & ",*",Table1[Status],"Done",Table1[Priority],"4") -> 0 | K6: =IF(C6=0,0,J6/C6) -> 0 | L6: Jon, Tom | M6: =IF(AND((D6/$C6)>D$2+0.05,$C6>4),2,IF(AND((D6/$C6)>D$2,$C6>4),1,0)) -> #DIV/0! | N6: =IF(AND((F6/$C6)>F$2+0.05,$C6>4),2,IF(AND((F6/$C6)>F$2,$C6>4),1,0)) -> #DIV/0! | O6: =IF(AND((H6/$C6)>H$2+0.05,$C6>4),2,IF(AND((H6/$C6)>H$2,$C6>4),1,0)) -> #DIV/0! | P6: =IF(AND((J6/$C6)>J$2,$C6>4),1,0) -> #DIV/0! | Q6: =SUM(D6,F6,H6,J6) -> 0 | S6: In Progress | T6: =COUNTIF(Table1[Status],'Checks and Stats'!S6)/(COUNTA(Table1[Status])-COUNTIF(Table1[Status],"Archive")) -> 0
B7: Ricky | C7: =COUNTIF(Table1[Assigned To],"*" & $B7) + COUNTIF(Table1[Assigned To],$B7 & ",*") - COUNTIFS(Table1[Assigned To],"*" & $B7,Table1[Status],"Archive") - COUNTIFS(Table1[Assigned To],$B7 & ",*",Table1[Status],"Archive") - COUNTIFS(Table1[Assigned To],"*" & $B7,Table1[Status],"Done") - COUNTIFS(Table1[Assigned To],$B7 & ",*",Table1[Status],"Done") -> 0 | D7: =COUNTIFS(Table1[Assigned To],"*" & $B7,Table1[Priority],"1") + COUNTIFS(Table1[Assigned To],$B7 & ",*",Table1[Priority],"1") - COUNTIFS(Table1[Assigned To],"*" & $B7,Table1[Status],"Archive",Table1[Priority],"1") - COUNTIFS(Table1[Assigned To],$B7 & ",*",Table1[Status],"Archive",Table1[Priority],"1") - COUNTIFS(Table1[Assigned To],"*" & $B7,Table1[Status],"Done",Table1[Priority],"1") - COUNTIFS(Table1[Assigned To],$B7 & ",*",Table1[Status],"Done",Table1[Priority],"1") -> 0 | E7: =IF(C7=0,0,D7/C7) -> 0 | F7: =COUNTIFS(Table1[Assigned To],"*" & $B7,Table1[Priority],"2") + COUNTIFS(Table1[Assigned To],$B7 & ",*",Table1[Priority],"2") - COUNTIFS(Table1[Assigned To],"*" & $B7,Table1[Status],"Archive",Table1[Priority],"2") - COUNTIFS(Table1[Assigned To],$B7 & ",*",Table1[Status],"Archive",Table1[Priority],"2") - COUNTIFS(Table1[Assigned To],"*" & $B7,Table1[Status],"Done",Table1[Priority],"2") - COUNTIFS(Table1[Assigned To],$B7 & ",*",Table1[Status],"Done",Table1[Priority],"2") -> 0 | G7: =IF(C7=0,0,F7/C7) -> 0 | H7: =COUNTIFS(Table1[Assigned To],"*" & $B7,Table1[Priority],"3") + COUNTIFS(Table1[Assigned To],$B7 & ",*",Table1[Priority],"3") - COUNTIFS(Table1[Assigned To],"*" & $B7,Table1[Status],"Archive",Table1[Priority],"3") - COUNTIFS(Table1[Assigned To],$B7 & ",*",Table1[Status],"Archive",Table1[Priority],"3") - COUNTIFS(Table1[Assigned To],"*" & $B7,Table1[Status],"Done",Table1[Priority],"3") - COUNTIFS(Table1[Assigned To],$B7 & ",*",Table1[Status],"Done",Table1[Priority],"3") -> 0 | I7: =IF(C7=0,0,H7/C7) -> 0 | J7: =COUNTIFS(Table1[Assigned To],"*" & $B7,Table1[Priority],"4") + COUNTIFS(Table1[Assigned To],$B7 & ",*",Table1[Priority],"4") - COUNTIFS(Table1[Assigned To],"*" & $B7,Table1[Status],"Archive",Table1[Priority],"4") - COUNTIFS(Table1[Assigned To],$B7 & ",*",Table1[Status],"Archive",Table1[Priority],"4") - COUNTIFS(Table1[Assigned To],"*" & $B7,Table1[Status],"Done",Table1[Priority],"4") - COUNTIFS(Table1[Assigned To],$B7 & ",*",Table1[Status],"Done",Table1[Priority],"4") -> 0 | K7: =IF(C7=0,0,J7/C7) -> 0 | L7: Brandon | M7: =IF(AND((D7/$C7)>D$2+0.05,$C7>4),2,IF(AND((D7/$C7)>D$2,$C7>4),1,0)) -> #DIV/0! | N7: =IF(AND((F7/$C7)>F$2+0.05,$C7>4),2,IF(AND((F7/$C7)>F$2,$C7>4),1,0)) -> #DIV/0! | O7: =IF(AND((H7/$C7)>H$2+0.05,$C7>4),2,IF(AND((H7/$C7)>H$2,$C7>4),1,0)) -> #DIV/0! | P7: =IF(AND((J7/$C7)>J$2,$C7>4),1,0) -> #DIV/0! | Q7: =SUM(D7,F7,H7,J7) -> 0
B8: Tom | C8: =COUNTIF(Table1[Assigned To],"*" & $B8) + COUNTIF(Table1[Assigned To],$B8 & ",*") - COUNTIFS(Table1[Assigned To],"*" & $B8,Table1[Status],"Archive") - COUNTIFS(Table1[Assigned To],$B8 & ",*",Table1[Status],"Archive") - COUNTIFS(Table1[Assigned To],"*" & $B8,Table1[Status],"Done") - COUNTIFS(Table1[Assigned To],$B8 & ",*",Table1[Status],"Done") -> 0 | D8: =COUNTIFS(Table1[Assigned To],"*" & $B8,Table1[Priority],"1") + COUNTIFS(Table1[Assigned To],$B8 & ",*",Table1[Priority],"1") - COUNTIFS(Table1[Assigned To],"*" & $B8,Table1[Status],"Archive",Table1[Priority],"1") - COUNTIFS(Table1[Assigned To],$B8 & ",*",Table1[Status],"Archive",Table1[Priority],"1") - COUNTIFS(Table1[Assigned To],"*" & $B8,Table1[Status],"Done",Table1[Priority],"1") - COUNTIFS(Table1[Assigned To],$B8 & ",*",Table1[Status],"Done",Table1[Priority],"1") -> 0 | E8: =IF(C8=0,0,D8/C8) -> 0 | F8: =COUNTIFS(Table1[Assigned To],"*" & $B8,Table1[Priority],"2") + COUNTIFS(Table1[Assigned To],$B8 & ",*",Table1[Priority],"2") - COUNTIFS(Table1[Assigned To],"*" & $B8,Table1[Status],"Archive",Table1[Priority],"2") - COUNTIFS(Table1[Assigned To],$B8 & ",*",Table1[Status],"Archive",Table1[Priority],"2") - COUNTIFS(Table1[Assigned To],"*" & $B8,Table1[Status],"Done",Table1[Priority],"2") - COUNTIFS(Table1[Assigned To],$B8 & ",*",Table1[Status],"Done",Table1[Priority],"2") -> 0 | G8: =IF(C8=0,0,F8/C8) -> 0 | H8: =COUNTIFS(Table1[Assigned To],"*" & $B8,Table1[Priority],"3") + COUNTIFS(Table1[Assigned To],$B8 & ",*",Table1[Priority],"3") - COUNTIFS(Table1[Assigned To],"*" & $B8,Table1[Status],"Archive",Table1[Priority],"3") - COUNTIFS(Table1[Assigned To],$B8 & ",*",Table1[Status],"Archive",Table1[Priority],"3") - COUNTIFS(Table1[Assigned To],"*" & $B8,Table1[Status],"Done",Table1[Priority],"3") - COUNTIFS(Table1[Assigned To],$B8 & ",*",Table1[Status],"Done",Table1[Priority],"3") -> 0 | I8: =IF(C8=0,0,H8/C8) -> 0 | J8: =COUNTIFS(Table1[Assigned To],"*" & $B8,Table1[Priority],"4") + COUNTIFS(Table1[Assigned To],$B8 & ",*",Table1[Priority],"4") - COUNTIFS(Table1[Assigned To],"*" & $B8,Table1[Status],"Archive",Table1[Priority],"4") - COUNTIFS(Table1[Assigned To],$B8 & ",*",Table1[Status],"Archive",Table1[Priority],"4") - COUNTIFS(Table1[Assigned To],"*" & $B8,Table1[Status],"Done",Table1[Priority],"4") - COUNTIFS(Table1[Assigned To],$B8 & ",*",Table1[Status],"Done",Table1[Priority],"4") -> 0 | K8: =IF(C8=0,0,J8/C8) -> 0 | L8: Nick | M8: =IF(AND((D8/$C8)>D$2+0.05,$C8>4),2,IF(AND((D8/$C8)>D$2,$C8>4),1,0)) -> #DIV/0! | N8: =IF(AND((F8/$C8)>F$2+0.05,$C8>4),2,IF(AND((F8/$C8)>F$2,$C8>4),1,0)) -> #DIV/0! | O8: =IF(AND((H8/$C8)>H$2+0.05,$C8>4),2,IF(AND((H8/$C8)>H$2,$C8>4),1,0)) -> #DIV/0! | P8: =IF(AND((J8/$C8)>J$2,$C8>4),1,0) -> #DIV/0! | Q8: =SUM(D8,F8,H8,J8) -> 0
B9: Mike | C9: =COUNTIF(Table1[Assigned To],"*" & $B9) + COUNTIF(Table1[Assigned To],$B9 & ",*") - COUNTIFS(Table1[Assigned To],"*" & $B9,Table1[Status],"Archive") - COUNTIFS(Table1[Assigned To],$B9 & ",*",Table1[Status],"Archive") - COUNTIFS(Table1[Assigned To],"*" & $B9,Table1[Status],"Done") - COUNTIFS(Table1[Assigned To],$B9 & ",*",Table1[Status],"Done") -> 0 | D9: =COUNTIFS(Table1[Assigned To],"*" & $B9,Table1[Priority],"1") + COUNTIFS(Table1[Assigned To],$B9 & ",*",Table1[Priority],"1") - COUNTIFS(Table1[Assigned To],"*" & $B9,Table1[Status],"Archive",Table1[Priority],"1") - COUNTIFS(Table1[Assigned To],$B9 & ",*",Table1[Status],"Archive",Table1[Priority],"1") - COUNTIFS(Table1[Assigned To],"*" & $B9,Table1[Status],"Done",Table1[Priority],"1") - COUNTIFS(Table1[Assigned To],$B9 & ",*",Table1[Status],"Done",Table1[Priority],"1") -> 0 | E9: =IF(C9=0,0,D9/C9) -> 0 | F9: =COUNTIFS(Table1[Assigned To],"*" & $B9,Table1[Priority],"2") + COUNTIFS(Table1[Assigned To],$B9 & ",*",Table1[Priority],"2") - COUNTIFS(Table1[Assigned To],"*" & $B9,Table1[Status],"Archive",Table1[Priority],"2") - COUNTIFS(Table1[Assigned To],$B9 & ",*",Table1[Status],"Archive",Table1[Priority],"2") - COUNTIFS(Table1[Assigned To],"*" & $B9,Table1[Status],"Done",Table1[Priority],"2") - COUNTIFS(Table1[Assigned To],$B9 & ",*",Table1[Status],"Done",Table1[Priority],"2") -> 0 | G9: =IF(C9=0,0,F9/C9) -> 0 | H9: =COUNTIFS(Table1[Assigned To],"*" & $B9,Table1[Priority],"3") + COUNTIFS(Table1[Assigned To],$B9 & ",*",Table1[Priority],"3") - COUNTIFS(Table1[Assigned To],"*" & $B9,Table1[Status],"Archive",Table1[Priority],"3") - COUNTIFS(Table1[Assigned To],$B9 & ",*",Table1[Status],"Archive",Table1[Priority],"3") - COUNTIFS(Table1[Assigned To],"*" & $B9,Table1[Status],"Done",Table1[Priority],"3") - COUNTIFS(Table1[Assigned To],$B9 & ",*",Table1[Status],"Done",Table1[Priority],"3") -> 0 | I9: =IF(C9=0,0,H9/C9) -> 0 | J9: =COUNTIFS(Table1[Assigned To],"*" & $B9,Table1[Priority],"4") + COUNTIFS(Table1[Assigned To],$B9 & ",*",Table1[Priority],"4") - COUNTIFS(Table1[Assigned To],"*" & $B9,Table1[Status],"Archive",Table1[Priority],"4") - COUNTIFS(Table1[Assigned To],$B9 & ",*",Table1[Status],"Archive",Table1[Priority],"4") - COUNTIFS(Table1[Assigned To],"*" & $B9,Table1[Status],"Done",Table1[Priority],"4") - COUNTIFS(Table1[Assigned To],$B9 & ",*",Table1[Status],"Done",Table1[Priority],"4") -> 0 | K9: =IF(C9=0,0,J9/C9) -> 0 | L9: Ricky, Jon | M9: =IF(AND((D9/$C9)>D$2+0.05,$C9>4),2,IF(AND((D9/$C9)>D$2,$C9>4),1,0)) -> #DIV/0! | N9: =IF(AND((F9/$C9)>F$2+0.05,$C9>4),2,IF(AND((F9/$C9)>F$2,$C9>4),1,0)) -> #DIV/0! | O9: =IF(AND((H9/$C9)>H$2+0.05,$C9>4),2,IF(AND((H9/$C9)>H$2,$C9>4),1,0)) -> #DIV/0! | P9: =IF(AND((J9/$C9)>J$2,$C9>4),1,0) -> #DIV/0! | Q9: =SUM(D9,F9,H9,J9) -> 0
B10: PB | C10: =COUNTIF(Table1[Assigned To],"*" & $B10) + COUNTIF(Table1[Assigned To],$B10 & ",*") - COUNTIFS(Table1[Assigned To],"*" & $B10,Table1[Status],"Archive") - COUNTIFS(Table1[Assigned To],$B10 & ",*",Table1[Status],"Archive") - COUNTIFS(Table1[Assigned To],"*" & $B10,Table1[Status],"Done") - COUNTIFS(Table1[Assigned To],$B10 & ",*",Table1[Status],"Done") -> 0 | D10: =COUNTIFS(Table1[Assigned To],"*" & $B10,Table1[Priority],"1") + COUNTIFS(Table1[Assigned To],$B10 & ",*",Table1[Priority],"1") - COUNTIFS(Table1[Assigned To],"*" & $B10,Table1[Status],"Archive",Table1[Priority],"1") - COUNTIFS(Table1[Assigned To],$B10 & ",*",Table1[Status],"Archive",Table1[Priority],"1") - COUNTIFS(Table1[Assigned To],"*" & $B10,Table1[Status],"Done",Table1[Priority],"1") - COUNTIFS(Table1[Assigned To],$B10 & ",*",Table1[Status],"Done",Table1[Priority],"1") -> 0 | E10: =IF(C10=0,0,D10/C10) -> 0 | F10: =COUNTIFS(Table1[Assigned To],"*" & $B10,Table1[Priority],"2") + COUNTIFS(Table1[Assigned To],$B10 & ",*",Table1[Priority],"2") - COUNTIFS(Table1[Assigned To],"*" & $B10,Table1[Status],"Archive",Table1[Priority],"2") - COUNTIFS(Table1[Assigned To],$B10 & ",*",Table1[Status],"Archive",Table1[Priority],"2") - COUNTIFS(Table1[Assigned To],"*" & $B10,Table1[Status],"Done",Table1[Priority],"2") - COUNTIFS(Table1[Assigned To],$B10 & ",*",Table1[Status],"Done",Table1[Priority],"2") -> 0 | G10: =IF(C10=0,0,F10/C10) -> 0 | H10: =COUNTIFS(Table1[Assigned To],"*" & $B10,Table1[Priority],"3") + COUNTIFS(Table1[Assigned To],$B10 & ",*",Table1[Priority],"3") - COUNTIFS(Table1[Assigned To],"*" & $B10,Table1[Status],"Archive",Table1[Priority],"3") - COUNTIFS(Table1[Assigned To],$B10 & ",*",Table1[Status],"Archive",Table1[Priority],"3") - COUNTIFS(Table1[Assigned To],"*" & $B10,Table1[Status],"Done",Table1[Priority],"3") - COUNTIFS(Table1[Assigned To],$B10 & ",*",Table1[Status],"Done",Table1[Priority],"3") -> 0 | I10: =IF(C10=0,0,H10/C10) -> 0 | J10: =COUNTIFS(Table1[Assigned To],"*" & $B10,Table1[Priority],"4") + COUNTIFS(Table1[Assigned To],$B10 & ",*",Table1[Priority],"4") - COUNTIFS(Table1[Assigned To],"*" & $B10,Table1[Status],"Archive",Table1[Priority],"4") - COUNTIFS(Table1[Assigned To],$B10 & ",*",Table1[Status],"Archive",Table1[Priority],"4") - COUNTIFS(Table1[Assigned To],"*" & $B10,Table1[Status],"Done",Table1[Priority],"4") - COUNTIFS(Table1[Assigned To],$B10 & ",*",Table1[Status],"Done",Table1[Priority],"4") -> 0 | K10: =IF(C10=0,0,J10/C10) -> 0 | L10: Tom, Jon | M10: =IF(AND((D10/$C10)>D$2+0.05,$C10>4),2,IF(AND((D10/$C10)>D$2,$C10>4),1,0)) -> #DIV/0! | N10: =IF(AND((F10/$C10)>F$2+0.05,$C10>4),2,IF(AND((F10/$C10)>F$2,$C10>4),1,0)) -> #DIV/0! | O10: =IF(AND((H10/$C10)>H$2+0.05,$C10>4),2,IF(AND((H10/$C10)>H$2,$C10>4),1,0)) -> #DIV/0! | P10: =IF(AND((J10/$C10)>J$2,$C10>4),1,0) -> #DIV/0! | Q10: =SUM(D10,F10,H10,J10) -> 0
B11: Notes | C11: =COUNTIF(Table1[Assigned To],"*" & $B11) + COUNTIF(Table1[Assigned To],$B11 & ",*") - COUNTIFS(Table1[Assigned To],"*" & $B11,Table1[Status],"Archive") - COUNTIFS(Table1[Assigned To],$B11 & ",*",Table1[Status],"Archive") - COUNTIFS(Table1[Assigned To],"*" & $B11,Table1[Status],"Done") - COUNTIFS(Table1[Assigned To],$B11 & ",*",Table1[Status],"Done") -> 0 | D11: =COUNTIFS(Table1[Assigned To],"*" & $B11,Table1[Priority],"1") + COUNTIFS(Table1[Assigned To],$B11 & ",*",Table1[Priority],"1") - COUNTIFS(Table1[Assigned To],"*" & $B11,Table1[Status],"Archive",Table1[Priority],"1") - COUNTIFS(Table1[Assigned To],$B11 & ",*",Table1[Status],"Archive",Table1[Priority],"1") - COUNTIFS(Table1[Assigned To],"*" & $B11,Table1[Status],"Done",Table1[Priority],"1") - COUNTIFS(Table1[Assigned To],$B11 & ",*",Table1[Status],"Done",Table1[Priority],"1") -> 0 | E11: =IF(C11=0,0,D11/C11) -> 0 | F11: =COUNTIFS(Table1[Assigned To],"*" & $B11,Table1[Priority],"2") + COUNTIFS(Table1[Assigned To],$B11 & ",*",Table1[Priority],"2") - COUNTIFS(Table1[Assigned To],"*" & $B11,Table1[Status],"Archive",Table1[Priority],"2") - COUNTIFS(Table1[Assigned To],$B11 & ",*",Table1[Status],"Archive",Table1[Priority],"2") - COUNTIFS(Table1[Assigned To],"*" & $B11,Table1[Status],"Done",Table1[Priority],"2") - COUNTIFS(Table1[Assigned To],$B11 & ",*",Table1[Status],"Done",Table1[Priority],"2") -> 0 | G11: =IF(C11=0,0,F11/C11) -> 0 | H11: =COUNTIFS(Table1[Assigned To],"*" & $B11,Table1[Priority],"3") + COUNTIFS(Table1[Assigned To],$B11 & ",*",Table1[Priority],"3") - COUNTIFS(Table1[Assigned To],"*" & $B11,Table1[Status],"Archive",Table1[Priority],"3") - COUNTIFS(Table1[Assigned To],$B11 & ",*",Table1[Status],"Archive",Table1[Priority],"3") - COUNTIFS(Table1[Assigned To],"*" & $B11,Table1[Status],"Done",Table1[Priority],"3") - COUNTIFS(Table1[Assigned To],$B11 & ",*",Table1[Status],"Done",Table1[Priority],"3") -> 0 | I11: =IF(C11=0,0,H11/C11) -> 0 | J11: =COUNTIFS(Table1[Assigned To],"*" & $B11,Table1[Priority],"4") + COUNTIFS(Table1[Assigned To],$B11 & ",*",Table1[Priority],"4") - COUNTIFS(Table1[Assigned To],"*" & $B11,Table1[Status],"Archive",Table1[Priority],"4") - COUNTIFS(Table1[Assigned To],$B11 & ",*",Table1[Status],"Archive",Table1[Priority],"4") - COUNTIFS(Table1[Assigned To],"*" & $B11,Table1[Status],"Done",Table1[Priority],"4") - COUNTIFS(Table1[Assigned To],$B11 & ",*",Table1[Status],"Done",Table1[Priority],"4") -> 0 | K11: =IF(C11=0,0,J11/C11) -> 0 | L11: Tom | M11: =IF(AND((D11/$C11)>D$2+0.05,$C11>4),2,IF(AND((D11/$C11)>D$2,$C11>4),1,0)) -> #DIV/0! | N11: =IF(AND((F11/$C11)>F$2+0.05,$C11>4),2,IF(AND((F11/$C11)>F$2,$C11>4),1,0)) -> #DIV/0! | O11: =IF(AND((H11/$C11)>H$2+0.05,$C11>4),2,IF(AND((H11/$C11)>H$2,$C11>4),1,0)) -> #DIV/0! | P11: =IF(AND((J11/$C11)>J$2,$C11>4),1,0) -> #DIV/0! | Q11: =SUM(D11,F11,H11,J11) -> 0
B12: Ben | C12: =COUNTIF(Table1[Assigned To],"*" & $B12) + COUNTIF(Table1[Assigned To],$B12 & ",*") - COUNTIFS(Table1[Assigned To],"*" & $B12,Table1[Status],"Archive") - COUNTIFS(Table1[Assigned To],$B12 & ",*",Table1[Status],"Archive") - COUNTIFS(Table1[Assigned To],"*" & $B12,Table1[Status],"Done") - COUNTIFS(Table1[Assigned To],$B12 & ",*",Table1[Status],"Done") -> 0 | D12: =COUNTIFS(Table1[Assigned To],"*" & $B12,Table1[Priority],"1") + COUNTIFS(Table1[Assigned To],$B12 & ",*",Table1[Priority],"1") - COUNTIFS(Table1[Assigned To],"*" & $B12,Table1[Status],"Archive",Table1[Priority],"1") - COUNTIFS(Table1[Assigned To],$B12 & ",*",Table1[Status],"Archive",Table1[Priority],"1") - COUNTIFS(Table1[Assigned To],"*" & $B12,Table1[Status],"Done",Table1[Priority],"1") - COUNTIFS(Table1[Assigned To],$B12 & ",*",Table1[Status],"Done",Table1[Priority],"1") -> 0 | E12: =IF(C12=0,0,D12/C12) -> 0 | F12: =COUNTIFS(Table1[Assigned To],"*" & $B12,Table1[Priority],"2") + COUNTIFS(Table1[Assigned To],$B12 & ",*",Table1[Priority],"2") - COUNTIFS(Table1[Assigned To],"*" & $B12,Table1[Status],"Archive",Table1[Priority],"2") - COUNTIFS(Table1[Assigned To],$B12 & ",*",Table1[Status],"Archive",Table1[Priority],"2") - COUNTIFS(Table1[Assigned To],"*" & $B12,Table1[Status],"Done",Table1[Priority],"2") - COUNTIFS(Table1[Assigned To],$B12 & ",*",Table1[Status],"Done",Table1[Priority],"2") -> 0 | G12: =IF(C12=0,0,F12/C12) -> 0 | H12: =COUNTIFS(Table1[Assigned To],"*" & $B12,Table1[Priority],"3") + COUNTIFS(Table1[Assigned To],$B12 & ",*",Table1[Priority],"3") - COUNTIFS(Table1[Assigned To],"*" & $B12,Table1[Status],"Archive",Table1[Priority],"3") - COUNTIFS(Table1[Assigned To],$B12 & ",*",Table1[Status],"Archive",Table1[Priority],"3") - COUNTIFS(Table1[Assigned To],"*" & $B12,Table1[Status],"Done",Table1[Priority],"3") - COUNTIFS(Table1[Assigned To],$B12 & ",*",Table1[Status],"Done",Table1[Priority],"3") -> 0 | I12: =IF(C12=0,0,H12/C12) -> 0 | J12: =COUNTIFS(Table1[Assigned To],"*" & $B12,Table1[Priority],"4") + COUNTIFS(Table1[Assigned To],$B12 & ",*",Table1[Priority],"4") - COUNTIFS(Table1[Assigned To],"*" & $B12,Table1[Status],"Archive",Table1[Priority],"4") - COUNTIFS(Table1[Assigned To],$B12 & ",*",Table1[Status],"Archive",Table1[Priority],"4") - COUNTIFS(Table1[Assigned To],"*" & $B12,Table1[Status],"Done",Table1[Priority],"4") - COUNTIFS(Table1[Assigned To],$B12 & ",*",Table1[Status],"Done",Table1[Priority],"4") -> 0 | K12: =IF(C12=0,0,J12/C12) -> 0 | L12: Mike | M12: =IF(AND((D12/$C12)>D$2+0.05,$C12>4),2,IF(AND((D12/$C12)>D$2,$C12>4),1,0)) -> #DIV/0! | N12: =IF(AND((F12/$C12)>F$2+0.05,$C12>4),2,IF(AND((F12/$C12)>F$2,$C12>4),1,0)) -> #DIV/0! | O12: =IF(AND((H12/$C12)>H$2+0.05,$C12>4),2,IF(AND((H12/$C12)>H$2,$C12>4),1,0)) -> #DIV/0! | P12: =IF(AND((J12/$C12)>J$2,$C12>4),1,0) -> #DIV/0! | Q12: =SUM(D12,F12,H12,J12) -> 0
B13: Jacob | C13: =COUNTIF(Table1[Assigned To],"*" & $B13) + COUNTIF(Table1[Assigned To],$B13 & ",*") - COUNTIFS(Table1[Assigned To],"*" & $B13,Table1[Status],"Archive") - COUNTIFS(Table1[Assigned To],$B13 & ",*",Table1[Status],"Archive") - COUNTIFS(Table1[Assigned To],"*" & $B13,Table1[Status],"Done") - COUNTIFS(Table1[Assigned To],$B13 & ",*",Table1[Status],"Done") -> 0 | D13: =COUNTIFS(Table1[Assigned To],"*" & $B13,Table1[Priority],"1") + COUNTIFS(Table1[Assigned To],$B13 & ",*",Table1[Priority],"1") - COUNTIFS(Table1[Assigned To],"*" & $B13,Table1[Status],"Archive",Table1[Priority],"1") - COUNTIFS(Table1[Assigned To],$B13 & ",*",Table1[Status],"Archive",Table1[Priority],"1") - COUNTIFS(Table1[Assigned To],"*" & $B13,Table1[Status],"Done",Table1[Priority],"1") - COUNTIFS(Table1[Assigned To],$B13 & ",*",Table1[Status],"Done",Table1[Priority],"1") -> 0 | E13: =IF(C13=0,0,D13/C13) -> 0 | F13: =COUNTIFS(Table1[Assigned To],"*" & $B13,Table1[Priority],"2") + COUNTIFS(Table1[Assigned To],$B13 & ",*",Table1[Priority],"2") - COUNTIFS(Table1[Assigned To],"*" & $B13,Table1[Status],"Archive",Table1[Priority],"2") - COUNTIFS(Table1[Assigned To],$B13 & ",*",Table1[Status],"Archive",Table1[Priority],"2") - COUNTIFS(Table1[Assigned To],"*" & $B13,Table1[Status],"Done",Table1[Priority],"2") - COUNTIFS(Table1[Assigned To],$B13 & ",*",Table1[Status],"Done",Table1[Priority],"2") -> 0 | G13: =IF(C13=0,0,F13/C13) -> 0 | H13: =COUNTIFS(Table1[Assigned To],"*" & $B13,Table1[Priority],"3") + COUNTIFS(Table1[Assigned To],$B13 & ",*",Table1[Priority],"3") - COUNTIFS(Table1[Assigned To],"*" & $B13,Table1[Status],"Archive",Table1[Priority],"3") - COUNTIFS(Table1[Assigned To],$B13 & ",*",Table1[Status],"Archive",Table1[Priority],"3") - COUNTIFS(Table1[Assigned To],"*" & $B13,Table1[Status],"Done",Table1[Priority],"3") - COUNTIFS(Table1[Assigned To],$B13 & ",*",Table1[Status],"Done",Table1[Priority],"3") -> 0 | I13: =IF(C13=0,0,H13/C13) -> 0 | J13: =COUNTIFS(Table1[Assigned To],"*" & $B13,Table1[Priority],"4") + COUNTIFS(Table1[Assigned To],$B13 & ",*",Table1[Priority],"4") - COUNTIFS(Table1[Assigned To],"*" & $B13,Table1[Status],"Archive",Table1[Priority],"4") - COUNTIFS(Table1[Assigned To],$B13 & ",*",Table1[Status],"Archive",Table1[Priority],"4") - COUNTIFS(Table1[Assigned To],"*" & $B13,Table1[Status],"Done",Table1[Priority],"4") - COUNTIFS(Table1[Assigned To],$B13 & ",*",Table1[Status],"Done",Table1[Priority],"4") -> 0 | K13: =IF(C13=0,0,J13/C13) -> 0 | L13: PB | M13: =IF(AND((D13/$C13)>D$2+0.05,$C13>4),2,IF(AND((D13/$C13)>D$2,$C13>4),1,0)) -> #DIV/0! | N13: =IF(AND((F13/$C13)>F$2+0.05,$C13>4),2,IF(AND((F13/$C13)>F$2,$C13>4),1,0)) -> #DIV/0! | O13: =IF(AND((H13/$C13)>H$2+0.05,$C13>4),2,IF(AND((H13/$C13)>H$2,$C13>4),1,0)) -> #DIV/0! | P13: =IF(AND((J13/$C13)>J$2,$C13>4),1,0) -> #DIV/0! | Q13: =SUM(D13,F13,H13,J13) -> 0
B14: Unassigned | C14: =COUNTIF(Table1[Assigned To],"*" & $B14) + COUNTIF(Table1[Assigned To],$B14 & ",*") - COUNTIFS(Table1[Assigned To],"*" & $B14,Table1[Status],"Archive") - COUNTIFS(Table1[Assigned To],$B14 & ",*",Table1[Status],"Archive") - COUNTIFS(Table1[Assigned To],"*" & $B14,Table1[Status],"Done") - COUNTIFS(Table1[Assigned To],$B14 & ",*",Table1[Status],"Done") -> 0 | D14: =COUNTIFS(Table1[Assigned To],"*" & $B14,Table1[Priority],"1") + COUNTIFS(Table1[Assigned To],$B14 & ",*",Table1[Priority],"1") - COUNTIFS(Table1[Assigned To],"*" & $B14,Table1[Status],"Archive",Table1[Priority],"1") - COUNTIFS(Table1[Assigned To],$B14 & ",*",Table1[Status],"Archive",Table1[Priority],"1") - COUNTIFS(Table1[Assigned To],"*" & $B14,Table1[Status],"Done",Table1[Priority],"1") - COUNTIFS(Table1[Assigned To],$B14 & ",*",Table1[Status],"Done",Table1[Priority],"1") -> 0 | E14: =IF(C14=0,0,D14/C14) -> 0 | F14: =COUNTIFS(Table1[Assigned To],"*" & $B14,Table1[Priority],"2") + COUNTIFS(Table1[Assigned To],$B14 & ",*",Table1[Priority],"2") - COUNTIFS(Table1[Assigned To],"*" & $B14,Table1[Status],"Archive",Table1[Priority],"2") - COUNTIFS(Table1[Assigned To],$B14 & ",*",Table1[Status],"Archive",Table1[Priority],"2") - COUNTIFS(Table1[Assigned To],"*" & $B14,Table1[Status],"Done",Table1[Priority],"2") - COUNTIFS(Table1[Assigned To],$B14 & ",*",Table1[Status],"Done",Table1[Priority],"2") -> 0 | G14: =IF(C14=0,0,F14/C14) -> 0 | H14: =COUNTIFS(Table1[Assigned To],"*" & $B14,Table1[Priority],"3") + COUNTIFS(Table1[Assigned To],$B14 & ",*",Table1[Priority],"3") - COUNTIFS(Table1[Assigned To],"*" & $B14,Table1[Status],"Archive",Table1[Priority],"3") - COUNTIFS(Table1[Assigned To],$B14 & ",*",Table1[Status],"Archive",Table1[Priority],"3") - COUNTIFS(Table1[Assigned To],"*" & $B14,Table1[Status],"Done",Table1[Priority],"3") - COUNTIFS(Table1[Assigned To],$B14 & ",*",Table1[Status],"Done",Table1[Priority],"3") -> 0 | I14: =IF(C14=0,0,H14/C14) -> 0 | J14: =COUNTIFS(Table1[Assigned To],"*" & $B14,Table1[Priority],"4") + COUNTIFS(Table1[Assigned To],$B14 & ",*",Table1[Priority],"4") - COUNTIFS(Table1[Assigned To],"*" & $B14,Table1[Status],"Archive",Table1[Priority],"4") - COUNTIFS(Table1[Assigned To],$B14 & ",*",Table1[Status],"Archive",Table1[Priority],"4") - COUNTIFS(Table1[Assigned To],"*" & $B14,Table1[Status],"Done",Table1[Priority],"4") - COUNTIFS(Table1[Assigned To],$B14 & ",*",Table1[Status],"Done",Table1[Priority],"4") -> 0 | K14: =IF(C14=0,0,J14/C14) -> 0 | L14: Notes | Q14: =SUM(D14,F14,H14,J14) -> 0
B15: David | C15: =COUNTIF(Table1[Assigned To],"*" & $B15) + COUNTIF(Table1[Assigned To],$B15 & ",*") - COUNTIFS(Table1[Assigned To],"*" & $B15,Table1[Status],"Archive") - COUNTIFS(Table1[Assigned To],$B15 & ",*",Table1[Status],"Archive") - COUNTIFS(Table1[Assigned To],"*" & $B15,Table1[Status],"Done") - COUNTIFS(Table1[Assigned To],$B15 & ",*",Table1[Status],"Done") -> 0 | D15: =COUNTIFS(Table1[Assigned To],"*" & $B15,Table1[Priority],"1") + COUNTIFS(Table1[Assigned To],$B15 & ",*",Table1[Priority],"1") - COUNTIFS(Table1[Assigned To],"*" & $B15,Table1[Status],"Archive",Table1[Priority],"1") - COUNTIFS(Table1[Assigned To],$B15 & ",*",Table1[Status],"Archive",Table1[Priority],"1") - COUNTIFS(Table1[Assigned To],"*" & $B15,Table1[Status],"Done",Table1[Priority],"1") - COUNTIFS(Table1[Assigned To],$B15 & ",*",Table1[Status],"Done",Table1[Priority],"1") -> 0 | E15: =IF(C15=0,0,D15/C15) -> 0 | F15: =COUNTIFS(Table1[Assigned To],"*" & $B15,Table1[Priority],"2") + COUNTIFS(Table1[Assigned To],$B15 & ",*",Table1[Priority],"2") - COUNTIFS(Table1[Assigned To],"*" & $B15,Table1[Status],"Archive",Table1[Priority],"2") - COUNTIFS(Table1[Assigned To],$B15 & ",*",Table1[Status],"Archive",Table1[Priority],"2") - COUNTIFS(Table1[Assigned To],"*" & $B15,Table1[Status],"Done",Table1[Priority],"2") - COUNTIFS(Table1[Assigned To],$B15 & ",*",Table1[Status],"Done",Table1[Priority],"2") -> 0 | G15: =IF(C15=0,0,F15/C15) -> 0 | H15: =COUNTIFS(Table1[Assigned To],"*" & $B15,Table1[Priority],"3") + COUNTIFS(Table1[Assigned To],$B15 & ",*",Table1[Priority],"3") - COUNTIFS(Table1[Assigned To],"*" & $B15,Table1[Status],"Archive",Table1[Priority],"3") - COUNTIFS(Table1[Assigned To],$B15 & ",*",Table1[Status],"Archive",Table1[Priority],"3") - COUNTIFS(Table1[Assigned To],"*" & $B15,Table1[Status],"Done",Table1[Priority],"3") - COUNTIFS(Table1[Assigned To],$B15 & ",*",Table1[Status],"Done",Table1[Priority],"3") -> 0 | I15: =IF(C15=0,0,H15/C15) -> 0 | J15: =COUNTIFS(Table1[Assigned To],"*" & $B15,Table1[Priority],"4") + COUNTIFS(Table1[Assigned To],$B15 & ",*",Table1[Priority],"4") - COUNTIFS(Table1[Assigned To],"*" & $B15,Table1[Status],"Archive",Table1[Priority],"4") - COUNTIFS(Table1[Assigned To],$B15 & ",*",Table1[Status],"Archive",Table1[Priority],"4") - COUNTIFS(Table1[Assigned To],"*" & $B15,Table1[Status],"Done",Table1[Priority],"4") - COUNTIFS(Table1[Assigned To],$B15 & ",*",Table1[Status],"Done",Table1[Priority],"4") -> 0 | K15: =IF(C15=0,0,J15/C15) -> 0 | L15: Ben | Q15: 0
B16: Sean | C16: =COUNTIF(Table1[Assigned To],"*" & $B16) + COUNTIF(Table1[Assigned To],$B16 & ",*") - COUNTIFS(Table1[Assigned To],"*" & $B16,Table1[Status],"Archive") - COUNTIFS(Table1[Assigned To],$B16 & ",*",Table1[Status],"Archive") - COUNTIFS(Table1[Assigned To],"*" & $B16,Table1[Status],"Done") - COUNTIFS(Table1[Assigned To],$B16 & ",*",Table1[Status],"Done") -> 0 | D16: =COUNTIFS(Table1[Assigned To],"*" & $B16,Table1[Priority],"1") + COUNTIFS(Table1[Assigned To],$B16 & ",*",Table1[Priority],"1") - COUNTIFS(Table1[Assigned To],"*" & $B16,Table1[Status],"Archive",Table1[Priority],"1") - COUNTIFS(Table1[Assigned To],$B16 & ",*",Table1[Status],"Archive",Table1[Priority],"1") - COUNTIFS(Table1[Assigned To],"*" & $B16,Table1[Status],"Done",Table1[Priority],"1") - COUNTIFS(Table1[Assigned To],$B16 & ",*",Table1[Status],"Done",Table1[Priority],"1") -> 0 | E16: =IF(C16=0,0,D16/C16) -> 0 | F16: =COUNTIFS(Table1[Assigned To],"*" & $B16,Table1[Priority],"2") + COUNTIFS(Table1[Assigned To],$B16 & ",*",Table1[Priority],"2") - COUNTIFS(Table1[Assigned To],"*" & $B16,Table1[Status],"Archive",Table1[Priority],"2") - COUNTIFS(Table1[Assigned To],$B16 & ",*",Table1[Status],"Archive",Table1[Priority],"2") - COUNTIFS(Table1[Assigned To],"*" & $B16,Table1[Status],"Done",Table1[Priority],"2") - COUNTIFS(Table1[Assigned To],$B16 & ",*",Table1[Status],"Done",Table1[Priority],"2") -> 0 | G16: =IF(C16=0,0,F16/C16) -> 0 | H16: =COUNTIFS(Table1[Assigned To],"*" & $B16,Table1[Priority],"3") + COUNTIFS(Table1[Assigned To],$B16 & ",*",Table1[Priority],"3") - COUNTIFS(Table1[Assigned To],"*" & $B16,Table1[Status],"Archive",Table1[Priority],"3") - COUNTIFS(Table1[Assigned To],$B16 & ",*",Table1[Status],"Archive",Table1[Priority],"3") - COUNTIFS(Table1[Assigned To],"*" & $B16,Table1[Status],"Done",Table1[Priority],"3") - COUNTIFS(Table1[Assigned To],$B16 & ",*",Table1[Status],"Done",Table1[Priority],"3") -> 0 | I16: =IF(C16=0,0,H16/C16) -> 0 | J16: =COUNTIFS(Table1[Assigned To],"*" & $B16,Table1[Priority],"4") + COUNTIFS(Table1[Assigned To],$B16 & ",*",Table1[Priority],"4") - COUNTIFS(Table1[Assigned To],"*" & $B16,Table1[Status],"Archive",Table1[Priority],"4") - COUNTIFS(Table1[Assigned To],$B16 & ",*",Table1[Status],"Archive",Table1[Priority],"4") - COUNTIFS(Table1[Assigned To],"*" & $B16,Table1[Status],"Done",Table1[Priority],"4") - COUNTIFS(Table1[Assigned To],$B16 & ",*",Table1[Status],"Done",Table1[Priority],"4") -> 0 | K16: =IF(C16=0,0,J16/C16) -> 0 | L16: Jon, Jacob | Q16: =SUM(D16,F16,H16,J16) -> 0
